
        
            # Parse and validate the field names.  Validation serves two purposes,
    # generating informative error messages and preventing template injection attacks.
    if isinstance(field_names, basestring):
        field_names = field_names.replace(',', ' ').split() # names separated by whitespace and/or commas
    field_names = tuple(map(str, field_names))
    for name in (typename,) + field_names:
        if not all(c.isalnum() or c=='_' for c in name):
            raise ValueError('Type names and field names can only contain alphanumeric characters and underscores: %r' % name)
        if _iskeyword(name):
            raise ValueError('Type names and field names cannot be a keyword: %r' % name)
        if name[0].isdigit():
            raise ValueError('Type names and field names cannot start with a number: %r' % name)
    seen_names = set()
    for name in field_names:
        if name.startswith('_'):
            raise ValueError('Field names cannot start with an underscore: %r' % name)
        if name in seen_names:
            raise ValueError('Encountered duplicate field name: %r' % name)
        seen_names.add(name)
    
            finished, pending = futures.wait(
                 [EXCEPTION_FUTURE, future1],
                 return_when=futures.FIRST_EXCEPTION)
    
    
class EventNotification( BaseRequest ):
  def __init__( self, event_name, buffer_number = None, extra_data = None ):
    super( EventNotification, self ).__init__()
    self._event_name = event_name
    self._buffer_number = buffer_number
    self._extra_data = extra_data
    self._response_future = None
    self._cached_response = None
    
      If the test fails (for the correct reason), then it is marked as skipped.
  If it fails for any other reason, it is marked as failed.
  If the test passes, then it is also marked as failed.'''
  def decorator( test ):
    @functools.wraps( test )
    def Wrapper( *args, **kwargs ):
      try:
        test( *args, **kwargs )
      except Exception as test_exception:
        # Ensure that we failed for the right reason
        test_exception_message = ToUnicode( test_exception )
        try:
          for matcher in exception_matchers:
            assert_that( test_exception_message, matcher )
        except AssertionError:
          # Failed for the wrong reason!
          import traceback
          print( 'Test failed for the wrong reason: ' + traceback.format_exc() )
          # Real failure reason is the *original* exception, we're only trapping
          # and ignoring the exception that is expected.
          raise test_exception